{
 "cells": [
  {
   "cell_type": "code",
   "execution_count": 2,
   "metadata": {},
   "outputs": [
    {
     "name": "stdout",
     "output_type": "stream",
     "text": [
      "2020-01-02 03:04:05+00:00\n",
      "(10, 20)\n"
     ]
    }
   ],
   "source": [
    "from datetime import datetime\n",
    "from typing import Tuple\n",
    "\n",
    "from pydantic import BaseModel\n",
    "\n",
    "\n",
    "class Delivery(BaseModel):\n",
    "    timestamp: datetime\n",
    "    dimensions: Tuple[int, int]\n",
    "\n",
    "\n",
    "m = Delivery(timestamp='2020-01-02T03:04:05Z', dimensions=['10', '20'])\n",
    "\n",
    "print((m.timestamp))\n",
    "#> datetime.datetime(2020, 1, 2, 3, 4, 5, tzinfo=TzInfo(UTC))\n",
    "print(m.dimensions)"
   ]
  },
  {
   "cell_type": "code",
   "execution_count": 3,
   "metadata": {},
   "outputs": [
    {
     "ename": "ValidationError",
     "evalue": "1 validation error for Delivery\ndimensions.0\n  Input should be a valid integer, unable to parse string as an integer [type=int_parsing, input_value='10.7', input_type=str]\n    For further information visit https://errors.pydantic.dev/2.4/v/int_parsing",
     "output_type": "error",
     "traceback": [
      "\u001b[1;31m---------------------------------------------------------------------------\u001b[0m",
      "\u001b[1;31mValidationError\u001b[0m                           Traceback (most recent call last)",
      "Cell \u001b[1;32mIn[3], line 1\u001b[0m\n\u001b[1;32m----> 1\u001b[0m m \u001b[38;5;241m=\u001b[39m \u001b[43mDelivery\u001b[49m\u001b[43m(\u001b[49m\u001b[43mtimestamp\u001b[49m\u001b[38;5;241;43m=\u001b[39;49m\u001b[38;5;124;43m'\u001b[39;49m\u001b[38;5;124;43m2020-01-02T03:04:05Z\u001b[39;49m\u001b[38;5;124;43m'\u001b[39;49m\u001b[43m,\u001b[49m\u001b[43m \u001b[49m\u001b[43mdimensions\u001b[49m\u001b[38;5;241;43m=\u001b[39;49m\u001b[43m[\u001b[49m\u001b[38;5;124;43m'\u001b[39;49m\u001b[38;5;124;43m10.7\u001b[39;49m\u001b[38;5;124;43m'\u001b[39;49m\u001b[43m,\u001b[49m\u001b[43m \u001b[49m\u001b[38;5;124;43m'\u001b[39;49m\u001b[38;5;124;43m20\u001b[39;49m\u001b[38;5;124;43m'\u001b[39;49m\u001b[43m]\u001b[49m\u001b[43m)\u001b[49m\n\u001b[0;32m      3\u001b[0m \u001b[38;5;28mprint\u001b[39m(\u001b[38;5;28mrepr\u001b[39m(m\u001b[38;5;241m.\u001b[39mtimestamp))\n\u001b[0;32m      4\u001b[0m \u001b[38;5;66;03m#> datetime.datetime(2020, 1, 2, 3, 4, 5, tzinfo=TzInfo(UTC))\u001b[39;00m\n",
      "File \u001b[1;32mc:\\Users\\HAZIQ\\miniconda3\\envs\\py12\\Lib\\site-packages\\pydantic\\main.py:164\u001b[0m, in \u001b[0;36mBaseModel.__init__\u001b[1;34m(__pydantic_self__, **data)\u001b[0m\n\u001b[0;32m    162\u001b[0m \u001b[38;5;66;03m# `__tracebackhide__` tells pytest and some other tools to omit this function from tracebacks\u001b[39;00m\n\u001b[0;32m    163\u001b[0m __tracebackhide__ \u001b[38;5;241m=\u001b[39m \u001b[38;5;28;01mTrue\u001b[39;00m\n\u001b[1;32m--> 164\u001b[0m \u001b[43m__pydantic_self__\u001b[49m\u001b[38;5;241;43m.\u001b[39;49m\u001b[43m__pydantic_validator__\u001b[49m\u001b[38;5;241;43m.\u001b[39;49m\u001b[43mvalidate_python\u001b[49m\u001b[43m(\u001b[49m\u001b[43mdata\u001b[49m\u001b[43m,\u001b[49m\u001b[43m \u001b[49m\u001b[43mself_instance\u001b[49m\u001b[38;5;241;43m=\u001b[39;49m\u001b[43m__pydantic_self__\u001b[49m\u001b[43m)\u001b[49m\n",
      "\u001b[1;31mValidationError\u001b[0m: 1 validation error for Delivery\ndimensions.0\n  Input should be a valid integer, unable to parse string as an integer [type=int_parsing, input_value='10.7', input_type=str]\n    For further information visit https://errors.pydantic.dev/2.4/v/int_parsing"
     ]
    }
   ],
   "source": [
    "m = Delivery(timestamp='2020-01-02T03:04:05Z', dimensions=['10.7', '20'])\n",
    "\n",
    "print(repr(m.timestamp))\n",
    "#> datetime.datetime(2020, 1, 2, 3, 4, 5, tzinfo=TzInfo(UTC))\n",
    "print(m.dimensions)\n",
    "#> (10, 20)"
   ]
  },
  {
   "cell_type": "code",
   "execution_count": 4,
   "metadata": {},
   "outputs": [
    {
     "name": "stdout",
     "output_type": "stream",
     "text": [
      "123\n"
     ]
    },
    {
     "data": {
      "text/plain": [
       "{'id': 123,\n",
       " 'name': 'Muhammad Qasim',\n",
       " 'signup_ts': datetime.datetime(2019, 6, 1, 12, 22),\n",
       " 'tastes': {'wine': 9, 'cheese': 7, 'cabbage': 1}}"
      ]
     },
     "metadata": {},
     "output_type": "display_data"
    }
   ],
   "source": [
    "from datetime import datetime\n",
    "\n",
    "from pydantic import BaseModel, PositiveInt\n",
    "\n",
    "\n",
    "class User(BaseModel):\n",
    "    id: int  \n",
    "    name: str = 'John Doe'  \n",
    "    signup_ts: datetime | None  \n",
    "    tastes: dict[str, PositiveInt]  \n",
    "\n",
    "\n",
    "external_data = {\n",
    "    'id': 123,\n",
    "    'signup_ts': '2019-06-01 12:22',  \n",
    "    'tastes': {\n",
    "        'wine': 9,\n",
    "        b'cheese': 7,  \n",
    "        'cabbage': '1',  \n",
    "    },\n",
    "    'name' : \"Muhammad Qasim\"\n",
    "}\n",
    "\n",
    "user = User(**external_data)  \n",
    "\n",
    "print(user.id)  \n",
    "#> 123\n",
    "display(user.model_dump())"
   ]
  },
  {
   "cell_type": "code",
   "execution_count": 5,
   "metadata": {},
   "outputs": [
    {
     "data": {
      "text/plain": [
       "[{'type': 'int_parsing',\n",
       "  'loc': ('id',),\n",
       "  'msg': 'Input should be a valid integer, unable to parse string as an integer',\n",
       "  'input': 'not an int',\n",
       "  'url': 'https://errors.pydantic.dev/2.4/v/int_parsing'},\n",
       " {'type': 'missing',\n",
       "  'loc': ('signup_ts',),\n",
       "  'msg': 'Field required',\n",
       "  'input': {'id': 'not an int', 'tastes': {}},\n",
       "  'url': 'https://errors.pydantic.dev/2.4/v/missing'}]"
      ]
     },
     "metadata": {},
     "output_type": "display_data"
    }
   ],
   "source": [
    "from pydantic import ValidationError\n",
    "\n",
    "\n",
    "class User(BaseModel):\n",
    "    id: int\n",
    "    name: str = 'John Doe'\n",
    "    signup_ts: datetime | None\n",
    "    tastes: dict[str, PositiveInt]\n",
    "\n",
    "\n",
    "external_data = {'id': 'not an int', 'tastes': {}}  \n",
    "\n",
    "try:\n",
    "    User(**external_data)  \n",
    "except ValidationError as e:\n",
    "    display(e.errors())"
   ]
  },
  {
   "cell_type": "code",
   "execution_count": 6,
   "metadata": {},
   "outputs": [
    {
     "ename": "ValidationError",
     "evalue": "2 validation errors for User\nid\n  Input should be a valid integer, unable to parse string as an integer [type=int_parsing, input_value='not an int', input_type=str]\n    For further information visit https://errors.pydantic.dev/2.4/v/int_parsing\nsignup_ts\n  Field required [type=missing, input_value={'id': 'not an int', 'tastes': {}}, input_type=dict]\n    For further information visit https://errors.pydantic.dev/2.4/v/missing",
     "output_type": "error",
     "traceback": [
      "\u001b[1;31m---------------------------------------------------------------------------\u001b[0m",
      "\u001b[1;31mValidationError\u001b[0m                           Traceback (most recent call last)",
      "Cell \u001b[1;32mIn[6], line 1\u001b[0m\n\u001b[1;32m----> 1\u001b[0m \u001b[43mUser\u001b[49m\u001b[43m(\u001b[49m\u001b[38;5;241;43m*\u001b[39;49m\u001b[38;5;241;43m*\u001b[39;49m\u001b[43mexternal_data\u001b[49m\u001b[43m)\u001b[49m\n",
      "File \u001b[1;32mc:\\Users\\HAZIQ\\miniconda3\\envs\\py12\\Lib\\site-packages\\pydantic\\main.py:164\u001b[0m, in \u001b[0;36mBaseModel.__init__\u001b[1;34m(__pydantic_self__, **data)\u001b[0m\n\u001b[0;32m    162\u001b[0m \u001b[38;5;66;03m# `__tracebackhide__` tells pytest and some other tools to omit this function from tracebacks\u001b[39;00m\n\u001b[0;32m    163\u001b[0m __tracebackhide__ \u001b[38;5;241m=\u001b[39m \u001b[38;5;28;01mTrue\u001b[39;00m\n\u001b[1;32m--> 164\u001b[0m \u001b[43m__pydantic_self__\u001b[49m\u001b[38;5;241;43m.\u001b[39;49m\u001b[43m__pydantic_validator__\u001b[49m\u001b[38;5;241;43m.\u001b[39;49m\u001b[43mvalidate_python\u001b[49m\u001b[43m(\u001b[49m\u001b[43mdata\u001b[49m\u001b[43m,\u001b[49m\u001b[43m \u001b[49m\u001b[43mself_instance\u001b[49m\u001b[38;5;241;43m=\u001b[39;49m\u001b[43m__pydantic_self__\u001b[49m\u001b[43m)\u001b[49m\n",
      "\u001b[1;31mValidationError\u001b[0m: 2 validation errors for User\nid\n  Input should be a valid integer, unable to parse string as an integer [type=int_parsing, input_value='not an int', input_type=str]\n    For further information visit https://errors.pydantic.dev/2.4/v/int_parsing\nsignup_ts\n  Field required [type=missing, input_value={'id': 'not an int', 'tastes': {}}, input_type=dict]\n    For further information visit https://errors.pydantic.dev/2.4/v/missing"
     ]
    }
   ],
   "source": [
    "User(**external_data)"
   ]
  }
 ],
 "metadata": {
  "kernelspec": {
   "display_name": "py12",
   "language": "python",
   "name": "python3"
  },
  "language_info": {
   "codemirror_mode": {
    "name": "ipython",
    "version": 3
   },
   "file_extension": ".py",
   "mimetype": "text/x-python",
   "name": "python",
   "nbconvert_exporter": "python",
   "pygments_lexer": "ipython3",
   "version": "3.12.0"
  }
 },
 "nbformat": 4,
 "nbformat_minor": 2
}
